<?xml version='1.0' encoding='utf-8'?>
<robot name="sharework_cell"><link name="world" /><joint name="base_to_right_leg" type="fixed"><parent link="world" /><child link="portal" /><origin xyz="0 0 0" /></joint><link name="portal" /><joint name="portal_to_right_column" type="fixed"><parent link="world" /><child link="right_column" /><origin xyz="-0.58 1.0 0" /></joint><joint name="portal_to_left_column" type="fixed"><parent link="world" /><child link="left_column" /><origin xyz="-0.58 -1.0 0" /></joint><link name="right_column"><visual><origin rpy="0 0 0" xyz="0.29 0.06 1.5" /><geometry><box size="0.58 0.12 3.0" /></geometry><material name="Grey"><color rgba="0.517647058823529 0.529411764705882 0.537254901960784 1" /></material></visual><collision><origin rpy="0 0 0" xyz="0.29 0.06 1.5" /><geometry><box size="0.6599999999999999 0.2 3.0" /></geometry><material name="Grey"><color rgba="0.517647058823529 0.529411764705882 0.537254901960784 1" /></material></collision></link><link name="left_column"><visual><origin rpy="0 0 0" xyz="0.29 -0.06 1.5" /><geometry><box size="0.58 0.12 3.0" /></geometry><material name="Grey"><color rgba="0.517647058823529 0.529411764705882 0.537254901960784 1" /></material></visual><collision><origin rpy="0 0 0" xyz="0.29 -0.06 1.5" /><geometry><box size="0.6599999999999999 0.2 3.0" /></geometry><material name="Grey"><color rgba="0.517647058823529 0.529411764705882 0.537254901960784 1" /></material></collision></link><joint name="portal_to_lower_beam" type="fixed"><parent link="world" /><child link="lower_beam" /><origin xyz="-0.58 0 0.895" /></joint><link name="lower_beam"><visual><origin rpy="0 0 0" xyz="0.29 0 -0.048" /><geometry><box size="0.58 2.0 0.12" /></geometry><material name="Grey"><color rgba="0.517647058823529 0.529411764705882 0.537254901960784 1" /></material></visual><collision><origin rpy="0 0 0" xyz="0.29 0 -0.048" /><geometry><box size="0.58 2.0 0.12" /></geometry><material name="Grey"><color rgba="0.517647058823529 0.529411764705882 0.537254901960784 1" /></material></collision></link><joint name="portal_to_upper_beam" type="fixed"><parent link="world" /><child link="upper_beam" /><origin xyz="-0.58 0 2.208" /></joint><link name="upper_beam"><visual><origin rpy="0 0 0" xyz="0.29 0 0.06" /><geometry><box size="0.58 2.0 0.12" /></geometry><material name="Grey"><color rgba="0.517647058823529 0.529411764705882 0.537254901960784 1" /></material></visual><collision><origin rpy="0 0 0" xyz="0.29 0 0.06" /><geometry><box size="0.58 2.0 0.12" /></geometry><material name="Grey"><color rgba="0.517647058823529 0.529411764705882 0.537254901960784 1" /></material></collision></link><joint name="upper_beam_guide" type="fixed"><parent link="upper_beam" /><child link="guide_fixed" /><origin xyz="0.325 -1.0 -0.14" /></joint><link name="guide_fixed"><visual><origin rpy="0 0 0" xyz="0 1.0 0.07" /><geometry><box size="0.28 2.0 0.14" /></geometry><material name="Grey"><color rgba="0.517647058823529 0.529411764705882 0.537254901960784 1" /></material></visual><collision><origin rpy="0 0 0" xyz="0 1.0 0.07" /><geometry><box size="0.5800000000000001 2.0 0.14" /></geometry><material name="Grey"><color rgba="0.517647058823529 0.529411764705882 0.537254901960784 1" /></material></collision></link><joint name="track_joint" type="fixed"><parent link="guide_fixed" /><child link="cursor" /><origin xyz="0 1.061 -0.01" /><limit effort="1000.0" lower="0" upper="1.4" velocity="0.5" /><axis xyz="0 1 0" /></joint><link name="cursor"><visual><origin rpy="0 0 0" xyz="0 0 0.005" /><geometry><box size="0.28 0.28 0.01" /></geometry><material name="DarkGrey"><color rgba="0.1 0.1 0.1 1" /></material></visual><collision><origin rpy="0 0 0" xyz="0 0 0.005" /><geometry><box size="0.28 0.28 0.01" /></geometry><material name="DarkGrey"><color rgba="0.1 0.1 0.1 1" /></material></collision></link><joint name="portal_to_table" type="fixed"><parent link="world" /><child link="table" /><origin xyz="0 -1.0 0.895" /></joint><link name="table"><visual><origin rpy="0 0 0" xyz="0.3 1.0 -0.02" /><geometry><box size="0.6 2.0 0.04" /></geometry><material name="Beech"><color rgba="0.952941176470588 0.694117647058823 0.392156862745098 1" /></material></visual><collision><origin rpy="0 0 0" xyz="0.3 1.0 -0.02" /><geometry><box size="0.6 2.0 0.04" /></geometry><material name="Beech"><color rgba="0.952941176470588 0.694117647058823 0.392156862745098 1" /></material></collision></link><joint name="table_to_rail" type="fixed"><parent link="table" /><child link="rail" /><origin xyz="0.3 -0.6120000000000001 0.12" /></joint><link name="rail"><visual><origin rpy="0 0 0" xyz="0 1.612 -0.06" /><geometry><box size="0.36 3.224 0.12" /></geometry><material name="Grey"><color rgba="0.517647058823529 0.529411764705882 0.537254901960784 1" /></material></visual><collision><origin rpy="0 0 0" xyz="0 1.612 -0.06" /><geometry><box size="0.36 3.224 0.12" /></geometry><material name="Grey"><color rgba="0.517647058823529 0.529411764705882 0.537254901960784 1" /></material></collision></link><joint name="portal_to_wall" type="fixed"><parent link="portal" /><child link="wall" /><origin xyz="-0.98 0 0" /></joint><link name="wall"><visual><origin rpy="0 0 0" xyz="-0.05 0 1.5" /><geometry><box size="0.1 4.24 3.0" /></geometry><material name="White"><color rgba="1 1 1 1" /></material></visual><collision><origin rpy="0 0 0" xyz="-0.05 0 1.5" /><geometry><box size="0.1 4.24 3.0" /></geometry><material name="White"><color rgba="1 1 1 1" /></material></collision></link><joint name="wall_to_ec" type="fixed"><parent link="wall" /><child link="electric_cabinet" /><origin xyz="0 0.3 0" /></joint><link name="electric_cabinet"><visual><origin rpy="0 0 0" xyz="0.2 0.35 1.0" /><geometry><box size="0.4 0.7 2.0" /></geometry><material name="White"><color rgba="1 1 1 1" /></material></visual><collision><origin rpy="0 0 0" xyz="0.2 0.35 1.0" /><geometry><box size="0.4 0.7 2.0" /></geometry><material name="White"><color rgba="1 1 1 1" /></material></collision></link><joint name="portal_to_floor" type="fixed"><parent link="portal" /><child link="floor" /><origin xyz="-0.98 0 0" /></joint><link name="floor"><visual><origin rpy="0 0 0" xyz="2.02 0 -0.005" /><geometry><box size="6 6 0.81" /></geometry><material name="White"><color rgba="1 1 1 0.1" /></material></visual></link><joint name="virtual_wall_1_joint" type="fixed"><parent link="guide_fixed" /><child link="virtual_wall_1" /><origin xyz="0 0 0.0" /></joint><link name="virtual_wall_1"><collision><origin rpy="0 0 0" xyz="-0.5 1.0 0.0005" /><geometry><box size="1.58 2.24 0.001" /></geometry><material name="VirtualWallColor"><color rgba="0.1 0.1 0.1 0.1" /></material></collision></link><joint name="virtual_wall_2_joint" type="fixed"><parent link="world" /><child link="virtual_wall_2" /><origin xyz="1.7000000000000002 0 0.0" /></joint><link name="virtual_wall_2"><collision><origin rpy="0 0 0" xyz="0.0005 0 1" /><geometry><box size="0.001 2.24 2" /></geometry><material name="VirtualWallColor2"><color rgba="0.1 0.1 0.1 0.1" /></material></collision></link><joint name="thing_on_wall_joint" type="fixed"><parent link="world" /><child link="thing_on_wall" /><origin xyz="0 0 0.0" /></joint><link name="thing_on_wall"><visual><origin rpy="0 0 0" xyz="-0.2 -0.95 1.35" /><geometry><box size="0.5 0.1 0.3" /></geometry><material name="Grey"><color rgba="0.517647058823529 0.529411764705882 0.537254901960784 1" /></material></visual><collision><origin rpy="0 0 0" xyz="-0.2 -0.95 1.35" /><geometry><box size="0.5 0.1 0.3" /></geometry><material name="Grey"><color rgba="0.517647058823529 0.529411764705882 0.537254901960784 1" /></material></collision></link><joint name="computer_screen_joint" type="fixed"><parent link="world" /><child link="computer_screen" /><origin xyz="0 0 0.0" /></joint><link name="computer_screen"><visual><origin rpy="0 0 0" xyz="0.15 1.2 1.5" /><geometry><box size="0.2 0.5 0.5" /></geometry><material name="Grey"><color rgba="0.517647058823529 0.529411764705882 0.537254901960784 1" /></material></visual><collision><origin rpy="0 0 0" xyz="0.15 1.2 1.5" /><geometry><box size="0.2 0.5 0.5" /></geometry><material name="Grey"><color rgba="0.517647058823529 0.529411764705882 0.537254901960784 1" /></material></collision></link><ros2_control name="ur10e" type="system"><hardware><plugin>mock_components/GenericSystem</plugin><param name="fake_sensor_commands">False</param><param name="state_following_offset">0.0</param><param name="calculate_dynamics">true</param></hardware><joint name="ur10e_shoulder_pan_joint"><command_interface name="position" /><command_interface name="velocity" /><state_interface name="position"><param name="initial_value">1.570796327</param></state_interface><state_interface name="velocity" /><state_interface name="effort" /></joint><joint name="ur10e_shoulder_lift_joint"><command_interface name="position" /><command_interface name="velocity" /><state_interface name="position"><param name="initial_value">-2.443460953</param></state_interface><state_interface name="velocity" /><state_interface name="effort" /></joint><joint name="ur10e_elbow_joint"><command_interface name="position" /><command_interface name="velocity" /><state_interface name="position"><param name="initial_value">2.443460953</param></state_interface><state_interface name="velocity" /><state_interface name="effort" /></joint><joint name="ur10e_wrist_1_joint"><command_interface name="position" /><command_interface name="velocity" /><state_interface name="position"><param name="initial_value">-1.570796327</param></state_interface><state_interface name="velocity" /><state_interface name="effort" /></joint><joint name="ur10e_wrist_2_joint"><command_interface name="position" /><command_interface name="velocity" /><state_interface name="position"><param name="initial_value">1.570796327</param></state_interface><state_interface name="velocity" /><state_interface name="effort" /></joint><joint name="ur10e_wrist_3_joint"><command_interface name="position" /><command_interface name="velocity" /><state_interface name="position"><param name="initial_value">0.0</param></state_interface><state_interface name="velocity" /><state_interface name="effort" /></joint><sensor name="ur10e_tcp_fts_sensor"><state_interface name="force.x" /><state_interface name="force.y" /><state_interface name="force.z" /><state_interface name="torque.x" /><state_interface name="torque.y" /><state_interface name="torque.z" /></sensor><sensor name="ur10e_tcp_pose"><state_interface name="position.x" /><state_interface name="position.y" /><state_interface name="position.z" /><state_interface name="orientation.x" /><state_interface name="orientation.y" /><state_interface name="orientation.z" /><state_interface name="orientation.w" /></sensor><gpio name="ur10e_speed_scaling"><state_interface name="speed_scaling_factor" /><param name="initial_speed_scaling_factor">1</param><command_interface name="target_speed_fraction_cmd" /><command_interface name="target_speed_fraction_async_success" /></gpio><gpio name="ur10e_gpio"><command_interface name="standard_digital_output_cmd_0" /><command_interface name="standard_digital_output_cmd_1" /><command_interface name="standard_digital_output_cmd_2" /><command_interface name="standard_digital_output_cmd_3" /><command_interface name="standard_digital_output_cmd_4" /><command_interface name="standard_digital_output_cmd_5" /><command_interface name="standard_digital_output_cmd_6" /><command_interface name="standard_digital_output_cmd_7" /><command_interface name="standard_digital_output_cmd_8" /><command_interface name="standard_digital_output_cmd_9" /><command_interface name="standard_digital_output_cmd_10" /><command_interface name="standard_digital_output_cmd_11" /><command_interface name="standard_digital_output_cmd_12" /><command_interface name="standard_digital_output_cmd_13" /><command_interface name="standard_digital_output_cmd_14" /><command_interface name="standard_digital_output_cmd_15" /><command_interface name="standard_digital_output_cmd_16" /><command_interface name="standard_digital_output_cmd_17" /><command_interface name="standard_analog_output_cmd_0" /><command_interface name="standard_analog_output_cmd_1" /><command_interface name="analog_output_domain_cmd" /><command_interface name="tool_voltage_cmd" /><command_interface name="io_async_success" /><state_interface name="digital_output_0" /><state_interface name="digital_output_1" /><state_interface name="digital_output_2" /><state_interface name="digital_output_3" /><state_interface name="digital_output_4" /><state_interface name="digital_output_5" /><state_interface name="digital_output_6" /><state_interface name="digital_output_7" /><state_interface name="digital_output_8" /><state_interface name="digital_output_9" /><state_interface name="digital_output_10" /><state_interface name="digital_output_11" /><state_interface name="digital_output_12" /><state_interface name="digital_output_13" /><state_interface name="digital_output_14" /><state_interface name="digital_output_15" /><state_interface name="digital_output_16" /><state_interface name="digital_output_17" /><state_interface name="digital_input_0" /><state_interface name="digital_input_1" /><state_interface name="digital_input_2" /><state_interface name="digital_input_3" /><state_interface name="digital_input_4" /><state_interface name="digital_input_5" /><state_interface name="digital_input_6" /><state_interface name="digital_input_7" /><state_interface name="digital_input_8" /><state_interface name="digital_input_9" /><state_interface name="digital_input_10" /><state_interface name="digital_input_11" /><state_interface name="digital_input_12" /><state_interface name="digital_input_13" /><state_interface name="digital_input_14" /><state_interface name="digital_input_15" /><state_interface name="digital_input_16" /><state_interface name="digital_input_17" /><state_interface name="standard_analog_output_0" /><state_interface name="standard_analog_output_1" /><state_interface name="standard_analog_input_0" /><state_interface name="standard_analog_input_1" /><state_interface name="analog_io_type_0" /><state_interface name="analog_io_type_1" /><state_interface name="analog_io_type_2" /><state_interface name="analog_io_type_3" /><state_interface name="tool_mode" /><state_interface name="tool_output_voltage" /><state_interface name="tool_output_current" /><state_interface name="tool_temperature" /><state_interface name="tool_analog_input_0" /><state_interface name="tool_analog_input_1" /><state_interface name="tool_analog_input_type_0" /><state_interface name="tool_analog_input_type_1" /><state_interface name="robot_mode" /><state_interface name="robot_status_bit_0" /><state_interface name="robot_status_bit_1" /><state_interface name="robot_status_bit_2" /><state_interface name="robot_status_bit_3" /><state_interface name="safety_mode" /><state_interface name="safety_status_bit_0" /><state_interface name="safety_status_bit_1" /><state_interface name="safety_status_bit_2" /><state_interface name="safety_status_bit_3" /><state_interface name="safety_status_bit_4" /><state_interface name="safety_status_bit_5" /><state_interface name="safety_status_bit_6" /><state_interface name="safety_status_bit_7" /><state_interface name="safety_status_bit_8" /><state_interface name="safety_status_bit_9" /><state_interface name="safety_status_bit_10" /><state_interface name="program_running" /></gpio><gpio name="ur10e_payload"><command_interface name="mass" /><command_interface name="cog.x" /><command_interface name="cog.y" /><command_interface name="cog.z" /><command_interface name="payload_async_success" /></gpio><gpio name="ur10e_resend_robot_program"><command_interface name="resend_robot_program_cmd" /><command_interface name="resend_robot_program_async_success" /></gpio><gpio name="ur10e_hand_back_control"><command_interface name="hand_back_control_cmd" /><command_interface name="hand_back_control_async_success" /></gpio><gpio name="ur10e_zero_ftsensor"><command_interface name="zero_ftsensor_cmd" /><command_interface name="zero_ftsensor_async_success" /></gpio><gpio name="ur10e_freedrive_mode"><command_interface name="async_success" /><command_interface name="enable" /><command_interface name="abort" /></gpio><gpio name="ur10e_system_interface"><state_interface name="initialized" /></gpio><gpio name="ur10e_force_mode"><command_interface name="task_frame_x" /><command_interface name="task_frame_y" /><command_interface name="task_frame_z" /><command_interface name="task_frame_rx" /><command_interface name="task_frame_ry" /><command_interface name="task_frame_rz" /><command_interface name="selection_vector_x" /><command_interface name="selection_vector_y" /><command_interface name="selection_vector_z" /><command_interface name="selection_vector_rx" /><command_interface name="selection_vector_ry" /><command_interface name="selection_vector_rz" /><command_interface name="wrench_x" /><command_interface name="wrench_y" /><command_interface name="wrench_z" /><command_interface name="wrench_rx" /><command_interface name="wrench_ry" /><command_interface name="wrench_rz" /><command_interface name="limits_x" /><command_interface name="limits_y" /><command_interface name="limits_z" /><command_interface name="limits_rx" /><command_interface name="limits_ry" /><command_interface name="limits_rz" /><command_interface name="type" /><command_interface name="damping" /><command_interface name="gain_scaling" /><command_interface name="disable_cmd" /><command_interface name="force_mode_async_success" /></gpio><gpio name="ur10e_trajectory_passthrough"><command_interface name="setpoint_positions_0" /><command_interface name="setpoint_positions_1" /><command_interface name="setpoint_positions_2" /><command_interface name="setpoint_positions_3" /><command_interface name="setpoint_positions_4" /><command_interface name="setpoint_positions_5" /><command_interface name="setpoint_velocities_0" /><command_interface name="setpoint_velocities_1" /><command_interface name="setpoint_velocities_2" /><command_interface name="setpoint_velocities_3" /><command_interface name="setpoint_velocities_4" /><command_interface name="setpoint_velocities_5" /><command_interface name="setpoint_accelerations_0" /><command_interface name="setpoint_accelerations_1" /><command_interface name="setpoint_accelerations_2" /><command_interface name="setpoint_accelerations_3" /><command_interface name="setpoint_accelerations_4" /><command_interface name="setpoint_accelerations_5" /><command_interface name="transfer_state" /><command_interface name="time_from_start" /><command_interface name="abort" /></gpio><gpio name="ur10e_get_robot_software_version"><state_interface name="get_version_major" /><state_interface name="get_version_minor" /><state_interface name="get_version_build" /><state_interface name="get_version_bugfix" /></gpio></ros2_control><link name="ur10e_base_link" /><link name="ur10e_base_link_inertia"><visual><origin rpy="0 0 3.141592653589793" xyz="0 0 0" /><geometry><mesh filename="assets/pkg/ur_description/meshes/ur10e/visual/base.dae" /></geometry></visual><collision><origin rpy="0 0 3.141592653589793" xyz="0 0 0" /><geometry><mesh filename="assets/pkg/ur_description/meshes/ur10e/collision/base.stl" /></geometry></collision><inertial><mass value="4.0" /><origin rpy="0 0 0" xyz="0 0 0" /><inertia ixx="0.0061063308908" ixy="0.0" ixz="0.0" iyy="0.0061063308908" iyz="0.0" izz="0.01125" /></inertial></link><link name="ur10e_shoulder_link"><visual><origin rpy="0 0 3.141592653589793" xyz="0 0 0" /><geometry><mesh filename="assets/pkg/ur_description/meshes/ur10e/visual/shoulder.dae" /></geometry></visual><collision><origin rpy="0 0 3.141592653589793" xyz="0 0 0" /><geometry><mesh filename="assets/pkg/ur_description/meshes/ur10e/collision/shoulder.stl" /></geometry></collision><inertial><mass value="7.369" /><origin rpy="1.570796326794897 0 0" xyz="0.021 -0.027 0.0" /><inertia ixx="0.03408" ixy="2e-05" ixz="-0.00425" iyy="0.03529" iyz="8e-05" izz="0.02156" /></inertial></link><link name="ur10e_upper_arm_link"><visual><origin rpy="1.5707963267948966 0 -1.5707963267948966" xyz="0 0 0.1762" /><geometry><mesh filename="assets/pkg/ur_description/meshes/ur10e/visual/upperarm.dae" /></geometry></visual><collision><origin rpy="1.5707963267948966 0 -1.5707963267948966" xyz="0 0 0.1762" /><geometry><mesh filename="assets/pkg/ur_description/meshes/ur10e/collision/upperarm.stl" /></geometry></collision><inertial><mass value="13.051" /><origin rpy="0 0 0" xyz="-0.2327 0.0 0.158" /><inertia ixx="0.02814" ixy="5e-05" ixz="-0.01561" iyy="0.77068" iyz="2e-05" izz="0.76943" /></inertial></link><link name="ur10e_forearm_link"><visual><origin rpy="1.5707963267948966 0 -1.5707963267948966" xyz="0 0 0.0393" /><geometry><mesh filename="assets/pkg/ur_description/meshes/ur10e/visual/forearm.dae" /></geometry></visual><collision><origin rpy="1.5707963267948966 0 -1.5707963267948966" xyz="0 0 0.0393" /><geometry><mesh filename="assets/pkg/ur_description/meshes/ur10e/collision/forearm.stl" /></geometry></collision><inertial><mass value="3.989" /><origin rpy="0 0 0" xyz="-0.33155 0.0 0.068" /><inertia ixx="0.01014" ixy="8e-05" ixz="0.00916" iyy="0.30928" iyz="0.0" izz="0.30646" /></inertial></link><link name="ur10e_wrist_1_link"><visual><origin rpy="1.5707963267948966 0 0" xyz="0 0 -0.135" /><geometry><mesh filename="assets/pkg/ur_description/meshes/ur10e/visual/wrist1.dae" /></geometry></visual><collision><origin rpy="1.5707963267948966 0 0" xyz="0 0 -0.135" /><geometry><mesh filename="assets/pkg/ur_description/meshes/ur10e/collision/wrist1.stl" /></geometry></collision><inertial><mass value="2.1" /><origin rpy="1.570796326794897 0 0" xyz="0.0 -0.018 0.007" /><inertia ixx="0.00296" ixy="-1e-05" ixz="0.0" iyy="0.00222" iyz="-0.00024" izz="0.00258" /></inertial></link><link name="ur10e_wrist_2_link"><visual><origin rpy="0 0 0" xyz="0 0 -0.12" /><geometry><mesh filename="assets/pkg/ur_description/meshes/ur10e/visual/wrist2.dae" /></geometry></visual><collision><origin rpy="0 0 0" xyz="0 0 -0.12" /><geometry><mesh filename="assets/pkg/ur_description/meshes/ur10e/collision/wrist2.stl" /></geometry></collision><inertial><mass value="1.98" /><origin rpy="-1.570796326794897 0 0" xyz="0.0 0.018 -0.007" /><inertia ixx="0.00296" ixy="-1e-05" ixz="0.0" iyy="0.00222" iyz="-0.00024" izz="0.00258" /></inertial></link><link name="ur10e_wrist_3_link"><visual><origin rpy="1.5707963267948966 0 0" xyz="0 0 -0.1168" /><geometry><mesh filename="assets/pkg/ur_description/meshes/ur10e/visual/wrist3.dae" /></geometry></visual><collision><origin rpy="1.5707963267948966 0 0" xyz="0 0 -0.1168" /><geometry><mesh filename="assets/pkg/ur_description/meshes/ur10e/collision/wrist3.stl" /></geometry></collision><inertial><mass value="0.615" /><origin rpy="0 0 0" xyz="0.0 0.0 -0.026" /><inertia ixx="0.0004" ixy="0.0" ixz="0.0" iyy="0.00041" iyz="0.0" izz="0.00034" /></inertial></link><joint name="ur10e_base_joint" type="fixed"><origin rpy="3.141592653589793 0.0 1.5707963267948966" xyz="0.0 0.0 0.0" /><parent link="cursor" /><child link="ur10e_base_link" /></joint><joint name="ur10e_base_link-base_link_inertia" type="fixed"><parent link="ur10e_base_link" /><child link="ur10e_base_link_inertia" /><origin rpy="0 0 3.141592653589793" xyz="0 0 0" /></joint><joint name="ur10e_shoulder_pan_joint" type="revolute"><parent link="ur10e_base_link_inertia" /><child link="ur10e_shoulder_link" /><origin rpy="0 0 -5.681537116101164e-08" xyz="0 0 0.1812369595612139" /><axis xyz="0 0 1" /><limit effort="330.0" lower="-3.141592653589793" upper="3.141592653589793" velocity="2.0943951023931953" /><dynamics damping="0" friction="0" /></joint><joint name="ur10e_shoulder_lift_joint" type="revolute"><parent link="ur10e_shoulder_link" /><child link="ur10e_upper_arm_link" /><origin rpy="1.571234322931965 0 -2.65322894683893e-06" xyz="-8.792654051589253e-05 0 0" /><axis xyz="0 0 1" /><limit effort="330.0" lower="-3.141592653589793" upper="0.05235987755982989" velocity="2.0943951023931953" /><dynamics damping="0" friction="0" /></joint><joint name="ur10e_elbow_joint" type="revolute"><parent link="ur10e_upper_arm_link" /><child link="ur10e_forearm_link" /><origin rpy="0.0006685683672481053 0.0009626857853689462 2.732284048217955e-06" xyz="-0.6121801947349813 0 0" /><axis xyz="0 0 1" /><limit effort="150.0" lower="-3.141592653589793" upper="3.141592653589793" velocity="3.141592653589793" /><dynamics damping="0" friction="0" /></joint><joint name="ur10e_wrist_1_joint" type="revolute"><parent link="ur10e_forearm_link" /><child link="ur10e_wrist_1_link" /><origin rpy="3.139891413463903 3.140677396542519 3.141591156697404" xyz="-0.5709010104944168 0.0002966689356048516 0.1743837597536871" /><axis xyz="0 0 1" /><limit effort="56.0" lower="-6.283185307179586" upper="6.283185307179586" velocity="3.141592653589793" /><dynamics damping="0" friction="0" /></joint><joint name="ur10e_wrist_2_joint" type="revolute"><parent link="ur10e_wrist_1_link" /><child link="ur10e_wrist_2_link" /><origin rpy="1.57098614732238 0 1.097571004999014e-06" xyz="4.867185823864961e-05 -0.1198472927249651 -2.274947659575111e-05" /><axis xyz="0 0 1" /><limit effort="56.0" lower="-6.283185307179586" upper="6.283185307179586" velocity="3.141592653589793" /><dynamics damping="0" friction="0" /></joint><joint name="ur10e_wrist_3_joint" type="revolute"><parent link="ur10e_wrist_2_link" /><child link="ur10e_wrist_3_link" /><origin rpy="1.57076096219631 3.141592653589793 3.141592581057134" xyz="-0.0001284994478715255 0.1156303551619035 -4.089221096405905e-06" /><axis xyz="0 0 1" /><limit effort="56.0" lower="-6.283185307179586" upper="6.283185307179586" velocity="3.141592653589793" /><dynamics damping="0" friction="0" /></joint><link name="ur10e_ft_frame" /><joint name="ur10e_wrist_3_link-ft_frame" type="fixed"><parent link="ur10e_wrist_3_link" /><child link="ur10e_ft_frame" /><origin rpy="3.141592653589793 0 0" xyz="0 0 0" /></joint><link name="ur10e_base" /><joint name="ur10e_base_link-base_fixed_joint" type="fixed"><origin rpy="0 0 3.141592653589793" xyz="0 0 0" /><parent link="ur10e_base_link" /><child link="ur10e_base" /></joint><link name="ur10e_flange" /><joint name="ur10e_wrist_3-flange" type="fixed"><parent link="ur10e_wrist_3_link" /><child link="ur10e_flange" /><origin rpy="0 -1.5707963267948966 -1.5707963267948966" xyz="0 0 0" /></joint><link name="ur10e_tool0" /><joint name="ur10e_flange-tool0" type="fixed"><origin rpy="1.5707963267948966 0 1.5707963267948966" xyz="0 0 0" /><parent link="ur10e_flange" /><child link="ur10e_tool0" /></joint><joint name="rq_coupler_joint" type="fixed"><parent link="ur10e_tool0" /><child link="robotiq_coupler" /><origin rpy="0.0 0.0 1.5707963267948966" xyz="0.0 0.0 0.0" /></joint><link name="robotiq_coupler"><visual><origin rpy="0 0 0" xyz="0 0 0" /><geometry><cylinder length="0.01" radius="0.0375" /></geometry><material name="RobotiqGrey"><color rgba="0.02 0.02 0.02 1" /></material></visual><collision><origin rpy="0 0 0" xyz="0 0 0" /><geometry><cylinder length="0.04" radius="0.0375" /></geometry></collision><inertial><mass value="0.5" /><inertia ixx="0.1" ixy="0.0" ixz="0.0" iyy="0.1" iyz="0.0" izz="0.4" /></inertial></link><ros2_control name="robotiq_gripper" type="system"><hardware><param name="use_dummy">false</param><plugin>mock_components/GenericSystem</plugin><param name="mock_sensor_commands">False</param><param name="state_following_offset">0.0</param></hardware><joint name="ur10e_robotiq_85_left_knuckle_joint"><command_interface name="position" /><state_interface name="position"><param name="initial_value">0.7929</param></state_interface><state_interface name="velocity"><param name="initial_value">0.0</param></state_interface></joint><joint name="ur10e_robotiq_85_right_knuckle_joint"><param name="mimic">ur10e_robotiq_85_left_knuckle_joint</param><param name="multiplier">-1</param><command_interface name="position" /><state_interface name="position" /><state_interface name="velocity" /></joint><joint name="ur10e_robotiq_85_left_inner_knuckle_joint"><param name="mimic">ur10e_robotiq_85_left_knuckle_joint</param><param name="multiplier">1</param><command_interface name="position" /><state_interface name="position" /><state_interface name="velocity" /></joint><joint name="ur10e_robotiq_85_right_inner_knuckle_joint"><param name="mimic">ur10e_robotiq_85_left_knuckle_joint</param><param name="multiplier">-1</param><command_interface name="position" /><state_interface name="position" /><state_interface name="velocity" /></joint><joint name="ur10e_robotiq_85_left_finger_tip_joint"><param name="mimic">ur10e_robotiq_85_left_knuckle_joint</param><param name="multiplier">-1</param><command_interface name="position" /><state_interface name="position" /><state_interface name="velocity" /></joint><joint name="ur10e_robotiq_85_right_finger_tip_joint"><param name="mimic">ur10e_robotiq_85_left_knuckle_joint</param><param name="multiplier">1</param><command_interface name="position" /><state_interface name="position" /><state_interface name="velocity" /></joint><gpio name="reactivate_gripper"><command_interface name="reactivate_gripper_cmd" /><command_interface name="reactivate_gripper_response" /></gpio></ros2_control><link name="ur10e_robotiq_85_base_link"><visual><geometry><mesh filename="assets/pkg/robotiq_description/meshes/visual/2f_85/robotiq_base.dae" /></geometry></visual><collision><geometry><mesh filename="assets/pkg/robotiq_description/meshes/collision/2f_85/robotiq_base.stl" /></geometry></collision><inertial><origin rpy="0 0 0" xyz="0.0 2.274e-05 0.03232288" /><mass value="6.6320197e-01" /><inertia ixx="5.1617816e-04" ixy="2.936e-8" ixz="0.0" iyy="5.8802208e-04" iyz="-3.2296e-7" izz="3.9462776e-04" /></inertial></link><link name="ur10e_robotiq_85_left_knuckle_link"><visual><geometry><mesh filename="assets/pkg/robotiq_description/meshes/visual/2f_85/left_knuckle.dae" /></geometry></visual><collision><geometry><mesh filename="assets/pkg/robotiq_description/meshes/collision/2f_85/left_knuckle.stl" /></geometry></collision><inertial><origin rpy="0 0 0" xyz="0.01213197 0.0002 -0.00058647" /><mass value="1.384773208e-02" /><inertia ixx="3.5232e-7" ixy="0.0" ixz="1.1744e-7" iyy="2.31944e-6" iyz="0" izz="2.23136e-6" /></inertial></link><link name="ur10e_robotiq_85_right_knuckle_link"><visual><geometry><mesh filename="assets/pkg/robotiq_description/meshes/visual/2f_85/right_knuckle.dae" /></geometry></visual><collision><geometry><mesh filename="assets/pkg/robotiq_description/meshes/collision/2f_85/right_knuckle.stl" /></geometry></collision><inertial><origin rpy="0 0 0" xyz="-0.01213197 0.0002 -0.00058647" /><mass value="1.384773208e-02" /><inertia ixx="3.5232e-7" ixy="0.0" ixz="-1.1744e-7" iyy="2.31944e-6" iyz="0.0" izz="2.23136e-6" /></inertial></link><link name="ur10e_robotiq_85_left_finger_link"><visual><geometry><mesh filename="assets/pkg/robotiq_description/meshes/visual/2f_85/left_finger.dae" /></geometry></visual><collision><geometry><mesh filename="assets/pkg/robotiq_description/meshes/collision/2f_85/left_finger.stl" /></geometry></collision><inertial><origin rpy="0 0 0" xyz="0.00346899 -0.00079447 0.01867121" /><mass value="4.260376752e-02" /><inertia ixx="1.385792000000000e-05" ixy="0.0" ixz="-2.17264e-06" iyy="1.183208e-05" iyz="0.0" izz="5.19672e-06" /></inertial></link><link name="ur10e_robotiq_85_right_finger_link"><visual><geometry><mesh filename="assets/pkg/robotiq_description/meshes/visual/2f_85/right_finger.dae" /></geometry></visual><collision><geometry><mesh filename="assets/pkg/robotiq_description/meshes/collision/2f_85/right_finger.stl" /></geometry></collision><inertial><origin rpy="0 0 0" xyz="-0.00346899 -5.53e-06 0.01867121" /><mass value="4.260376752000000e-02" /><inertia ixx="1.385792e-05" ixy="0.0" ixz="2.17264e-06" iyy="1.183208e-05" iyz="0.0" izz="5.19672e-06" /></inertial></link><link name="ur10e_robotiq_85_left_inner_knuckle_link"><visual><geometry><mesh filename="assets/pkg/robotiq_description/meshes/visual/2f_85/left_inner_knuckle.dae" /></geometry></visual><collision><geometry><mesh filename="assets/pkg/robotiq_description/meshes/collision/2f_85/left_inner_knuckle.stl" /></geometry></collision><inertial><origin rpy="0 0 0" xyz="0.01897699 0.00015001 0.02247101" /><mass value="2.969376448e-02" /><inertia ixx="9.57136e-06" ixy="0.0" ixz="-3.93424e-06" iyy="8.69056e-06" iyz="0.0" izz="8.19144e-06" /></inertial></link><link name="ur10e_robotiq_85_right_inner_knuckle_link"><visual><geometry><mesh filename="assets/pkg/robotiq_description/meshes/visual/2f_85/right_inner_knuckle.dae" /></geometry></visual><collision><geometry><mesh filename="assets/pkg/robotiq_description/meshes/collision/2f_85/right_inner_knuckle.stl" /></geometry></collision><inertial><origin rpy="0 0 0" xyz="-0.01926824 5.001e-05 0.02222178" /><mass value="2.969376448e-02" /><inertia ixx="9.42456e-06" ixy="0.0" ixz="3.9636e-06" iyy="8.69056e-06" iyz="0.0" izz="8.33824e-06" /></inertial></link><link name="ur10e_robotiq_85_left_finger_tip_link"><visual><geometry><mesh filename="assets/pkg/robotiq_description/meshes/visual/2f_85/left_finger_tip.dae" /></geometry></visual><collision><geometry><mesh filename="assets/pkg/robotiq_description/meshes/collision/2f_85/left_finger_tip.stl" /></geometry><surface><friction><ode><mu1>100000.0</mu1><mu2>100000.0</mu2></ode></friction><contact><ode><kp>1e+5</kp><kd>1</kd><soft_cfm>0</soft_cfm><soft_erp>0.2</soft_erp><minDepth>0.002</minDepth><maxVel>0</maxVel></ode></contact></surface></collision><inertial><origin rpy="0 0 0" xyz="-0.01456706 -0.0008 0.01649701" /><mass value="4.268588744e-02" /><inertia ixx="1.048152e-05" ixy="0.0" ixz="3.5232e-6" iyy="1.197888e-05" iyz="0.0" izz="4.22784e-06" /></inertial></link><link name="ur10e_robotiq_85_right_finger_tip_link"><visual><geometry><mesh filename="assets/pkg/robotiq_description/meshes/visual/2f_85/right_finger_tip.dae" /></geometry></visual><collision><geometry><mesh filename="assets/pkg/robotiq_description/meshes/collision/2f_85/right_finger_tip.stl" /></geometry><surface><friction><ode><mu1>100000.0</mu1><mu2>100000.0</mu2></ode></friction><contact><ode><kp>1e+5</kp><kd>1</kd><soft_cfm>0</soft_cfm><soft_erp>0.2</soft_erp><minDepth>0.002</minDepth><maxVel>0</maxVel></ode></contact></surface></collision><inertial><origin rpy="0 0 0" xyz="0.01456706 5e-05 0.01649701" /><mass value="4.268588744e-02" /><inertia ixx="1.048152e-05" ixy="0.0" ixz="-3.5232e-06" iyy="1.197888e-05" iyz="0.0" izz="4.22784e-06" /></inertial></link><joint name="ur10e_robotiq_85_base_joint" type="fixed"><parent link="robotiq_coupler" /><child link="ur10e_robotiq_85_base_link" /><origin rpy="0 0 -1.5707963267948966" xyz="0 0 0" /></joint><joint name="ur10e_robotiq_85_left_knuckle_joint" type="revolute"><parent link="ur10e_robotiq_85_base_link" /><child link="ur10e_robotiq_85_left_knuckle_link" /><axis xyz="0 -1 0" /><origin rpy="0 0 0" xyz="0.03060114 0.0 0.05490452" /><limit effort="50" lower="0.0" upper="0.8" velocity="0.5" /></joint><joint name="ur10e_robotiq_85_right_knuckle_joint" type="revolute"><parent link="ur10e_robotiq_85_base_link" /><child link="ur10e_robotiq_85_right_knuckle_link" /><axis xyz="0 -1 0" /><origin rpy="0 0 0" xyz="-0.03060114 0.0 0.05490452" /><limit effort="50" lower="-0.8" upper="0.0" velocity="0.5" /><mimic joint="ur10e_robotiq_85_left_knuckle_joint" multiplier="-1" /></joint><joint name="ur10e_robotiq_85_left_finger_joint" type="fixed"><parent link="ur10e_robotiq_85_left_knuckle_link" /><child link="ur10e_robotiq_85_left_finger_link" /><origin rpy="0 0 0" xyz="0.03152616 0.0 -0.00376347" /></joint><joint name="ur10e_robotiq_85_right_finger_joint" type="fixed"><parent link="ur10e_robotiq_85_right_knuckle_link" /><child link="ur10e_robotiq_85_right_finger_link" /><origin rpy="0 0 0" xyz="-0.03152616 0.0 -0.00376347" /></joint><joint name="ur10e_robotiq_85_left_inner_knuckle_joint" type="continuous"><parent link="ur10e_robotiq_85_base_link" /><child link="ur10e_robotiq_85_left_inner_knuckle_link" /><axis xyz="0 -1 0" /><origin rpy="0 0 0" xyz="0.0127 0.0 0.06142" /><mimic joint="ur10e_robotiq_85_left_knuckle_joint" /></joint><joint name="ur10e_robotiq_85_right_inner_knuckle_joint" type="continuous"><parent link="ur10e_robotiq_85_base_link" /><child link="ur10e_robotiq_85_right_inner_knuckle_link" /><axis xyz="0 -1 0" /><origin rpy="0 0 0" xyz="-0.0127 0.0 0.06142" /><mimic joint="ur10e_robotiq_85_left_knuckle_joint" multiplier="-1" /></joint><joint name="ur10e_robotiq_85_left_finger_tip_joint" type="continuous"><parent link="ur10e_robotiq_85_left_finger_link" /><child link="ur10e_robotiq_85_left_finger_tip_link" /><axis xyz="0 -1 0" /><origin rpy="0 0 0" xyz="0.00563134 0.0 0.04718515" /><mimic joint="ur10e_robotiq_85_left_knuckle_joint" multiplier="-1" /></joint><joint name="ur10e_robotiq_85_right_finger_tip_joint" type="continuous"><parent link="ur10e_robotiq_85_right_finger_link" /><child link="ur10e_robotiq_85_right_finger_tip_link" /><axis xyz="0 -1 0" /><origin rpy="0 0 0" xyz="-0.00563134 0.0 0.04718515" /><mimic joint="ur10e_robotiq_85_left_knuckle_joint" /></joint><link name="open_tip" /><joint name="open_tip_joint" type="fixed"><parent link="robotiq_coupler" /><child link="open_tip" /><origin rpy="0 0 -1.5707963267948966" xyz="0 0 0.149" /></joint><link name="closed_tip" /><joint name="closed_tip_joint" type="fixed"><parent link="robotiq_coupler" /><child link="closed_tip" /><origin rpy="0 0 -1.5707963267948966" xyz="0 0 0.163" /></joint><joint name="rq_connector_joint" type="fixed"><parent link="robotiq_coupler" /><child link="rq_connector" /><origin rpy="0 0 0" xyz="-0.055 0 -0.02" /></joint><link name="rq_connector"><visual><origin rpy="0 0 0" xyz="0 0 0" /><geometry><box size="0.02 0.02 0.05" /></geometry><material name="RobotiqGrey"><color rgba="0.02 0.02 0.02 1" /></material></visual><collision><origin rpy="0 0 0" xyz="0 0 0" /><geometry><box size="0.02 0.02 0.05" /></geometry></collision></link><joint name="zed_world_joint" type="fixed"><parent link="world" /><child link="zed_camera_link" /><origin rpy="0.825 0.933 0.752" xyz="0.100575 -0.9304 2.31042" /></joint><material name="zed_mat"><color rgba="0.8 0.8 0.8 1.0" /></material><material name="zedm_mat"><color rgba="0 0 0 1.0" /></material><material name="zed2_mat"><color rgba="0.25 0.25 0.25 1.0" /></material><material name="zed2i_mat"><color rgba="0.25 0.25 0.25 1.0" /></material><material name="zedx_mat"><color rgba="0.25 0.25 0.25 1.0" /></material><material name="zedxm_mat"><color rgba="0.25 0.25 0.25 1.0" /></material><material name="virtual_mat"><color rgba="0.25 0.25 0.25 1.0" /></material><material name="zedxonegs_mat"><color rgba="0.25 0.25 0.25 1.0" /></material><material name="zedxone4k_mat"><color rgba="0.25 0.25 0.25 1.0" /></material><link name="zed_camera_link" /><link name="zed_camera_center"><visual><origin rpy="0 0 0" xyz="0.0 0 0.0" /><geometry><mesh filename="assets/pkg/zed/meshes/zed2.stl" /></geometry><material name="zed2_mat" /></visual><collision><origin rpy="0 0 0" xyz="0.0 0 0.0" /><geometry><mesh filename="assets/pkg/zed/meshes/zed2.stl" /></geometry></collision></link><joint name="zed_camera_center_joint" type="fixed"><parent link="zed_camera_link" /><child link="zed_camera_center" /><origin rpy="0 0.05 0" xyz="0 0 0.015" /></joint><link name="zed_left_camera_frame" /><joint name="zed_left_camera_joint" type="fixed"><parent link="zed_camera_center" /><child link="zed_left_camera_frame" /><origin rpy="0 0 0" xyz="-0.01 0.06 0" /></joint><link name="zed_left_camera_optical_frame" /><joint name="zed_left_camera_optical_joint" type="fixed"><origin rpy="-1.5707963267948966 0.0 -1.5707963267948966" xyz="0 0 0" /><parent link="zed_left_camera_frame" /><child link="zed_left_camera_optical_frame" /></joint><link name="zed_right_camera_frame" /><joint name="zed_right_camera_joint" type="fixed"><parent link="zed_camera_center" /><child link="zed_right_camera_frame" /><origin rpy="0 0 0" xyz="-0.01 -0.06 0" /></joint><link name="zed_right_camera_optical_frame" /><joint name="zed_right_camera_optical_joint" type="fixed"><origin rpy="-1.5707963267948966 0.0 -1.5707963267948966" xyz="0 0 0" /><parent link="zed_right_camera_frame" /><child link="zed_right_camera_optical_frame" /></joint><link name="zed_mag_link" /><joint name="zed_mag_joint" type="fixed"><parent link="zed_camera_center" /><child link="zed_mag_link" /><origin rpy="0 0 0" xyz="0 0 0" /></joint><link name="zed_baro_link" /><joint name="zed_baro_joint" type="fixed"><parent link="zed_camera_center" /><child link="zed_baro_link" /><origin rpy="0 0 0" xyz="0 0 0" /></joint><link name="zed_temp_left_link" /><joint name="zed_temp_left_joint" type="fixed"><parent link="zed_left_camera_frame" /><child link="zed_temp_left_link" /><origin rpy="0 0 0" xyz="0 0 0" /></joint><link name="zed_temp_right_link" /><joint name="zed_temp_right_joint" type="fixed"><parent link="zed_right_camera_frame" /><child link="zed_temp_right_link" /><origin rpy="0 0 0" xyz="0 0 0" /></joint><link name="rs1_camera_link" /><joint name="rs1_world_joint" type="fixed"><parent link="world" /><child link="rs1_camera_link" /><origin rpy="0.0773 0.773 -1.553" xyz="0.845205 1.15052 2.57347" /></joint><material name="aluminum"><color rgba="0.5 0.5 0.5 1" /></material><material name="plastic"><color rgba="0.1 0.1 0.1 1" /></material><joint name="rs1_joint" type="fixed"><origin rpy="0.0 0.0 0.0" xyz="0.0 0.0 0.0" /><parent link="rs1_camera_link" /><child link="rs1_bottom_screw_frame" /></joint><link name="rs1_bottom_screw_frame" /><joint name="rs1_link_joint" type="fixed"><origin rpy="0 0 0" xyz="0.010600000000000002 0.0175 0.0125" /><parent link="rs1_bottom_screw_frame" /><child link="rs1_link" /></joint><link name="rs1_link"><visual><origin rpy="1.5707963267948966 0 1.5707963267948966" xyz="0.0043 -0.0175 0" /><geometry><mesh filename="assets/abs/realsense2_description/meshes/d435.dae" /></geometry></visual><collision><origin rpy="0 0 0" xyz="0 -0.0175 0" /><geometry><box size="0.02505 0.09 0.025" /></geometry></collision><inertial><mass value="0.072" /><origin xyz="0 0 0" /><inertia ixx="0.003881243" ixy="0.0" ixz="0.0" iyy="0.000498940" iyz="0.0" izz="0.003879257" /></inertial></link><link name="rs2_camera_link" /><joint name="rs2_world_joint" type="fixed"><parent link="world" /><child link="rs2_camera_link" /><origin rpy="-0.0696 0.795 1.502" xyz="0.649999 -1.16584 2.63428" /></joint><joint name="rs2_joint" type="fixed"><origin rpy="0.0 0.0 0.0" xyz="0.0 0.0 0.0" /><parent link="rs2_camera_link" /><child link="rs2_bottom_screw_frame" /></joint><link name="rs2_bottom_screw_frame" /><joint name="rs2_link_joint" type="fixed"><origin rpy="0 0 0" xyz="0.010600000000000002 0.0175 0.0125" /><parent link="rs2_bottom_screw_frame" /><child link="rs2_link" /></joint><link name="rs2_link"><visual><origin rpy="1.5707963267948966 0 1.5707963267948966" xyz="0.0043 -0.0175 0" /><geometry><mesh filename="assets/abs/realsense2_description/meshes/d435.dae" /></geometry></visual><collision><origin rpy="0 0 0" xyz="0 -0.0175 0" /><geometry><box size="0.02505 0.09 0.025" /></geometry></collision><inertial><mass value="0.072" /><origin xyz="0 0 0" /><inertia ixx="0.003881243" ixy="0.0" ixz="0.0" iyy="0.000498940" iyz="0.0" izz="0.003879257" /></inertial></link></robot>
